ERROR:root:[ERROR] Attempt 1 failed to connect to https://mirror.reisenbauer.ee/archlinux/: HTTPSConnectionPool(host='mirror.reisenbauer.ee', port=443): Max retries exceeded with url: /archlinux/core/os/x86_64/core.db (Caused by NewConnectionError('<urllib3.connection.HTTPSConnection object at 0x7fb447e8e300>: Failed to establish a new connection: [Errno -2] Name or service not known'))
ERROR:root:[ERROR] Attempt 1 failed to connect to http://mirror.reisenbauer.ee/archlinux/: HTTPConnectionPool(host='mirror.reisenbauer.ee', port=80): Max retries exceeded with url: /archlinux/core/os/x86_64/core.db (Caused by NewConnectionError('<urllib3.connection.HTTPConnection object at 0x7fb447e4a900>: Failed to establish a new connection: [Errno -2] Name or service not known'))
ERROR:root:[ERROR] Attempt 2 failed to connect to http://mirror.reisenbauer.ee/archlinux/: HTTPConnectionPool(host='mirror.reisenbauer.ee', port=80): Max retries exceeded with url: /archlinux/core/os/x86_64/core.db (Caused by NewConnectionError('<urllib3.connection.HTTPConnection object at 0x7fb447e4a990>: Failed to establish a new connection: [Errno -2] Name or service not known'))
ERROR:root:[ERROR] Attempt 2 failed to connect to https://mirror.reisenbauer.ee/archlinux/: HTTPSConnectionPool(host='mirror.reisenbauer.ee', port=443): Max retries exceeded with url: /archlinux/core/os/x86_64/core.db (Caused by NewConnectionError('<urllib3.connection.HTTPSConnection object at 0x7fb447e4b200>: Failed to establish a new connection: [Errno -2] Name or service not known'))
ERROR:root:[ERROR] Attempt 1 failed to connect to https://mirror.hostart.az/archlinux/: HTTPSConnectionPool(host='mirror.hostart.az', port=443): Max retries exceeded with url: /archlinux/core/os/x86_64/core.db (Caused by NewConnectionError('<urllib3.connection.HTTPSConnection object at 0x7fb447e8c890>: Failed to establish a new connection: [Errno 113] No route to host'))
ERROR:root:[ERROR] Attempt 1 failed to connect to http://mirror.hostart.az/archlinux/: HTTPConnectionPool(host='mirror.hostart.az', port=80): Max retries exceeded with url: /archlinux/core/os/x86_64/core.db (Caused by NewConnectionError('<urllib3.connection.HTTPConnection object at 0x7fb447e4b140>: Failed to establish a new connection: [Errno 113] No route to host'))
ERROR:root:[ERROR] Attempt 3 failed to connect to http://mirror.reisenbauer.ee/archlinux/: HTTPConnectionPool(host='mirror.reisenbauer.ee', port=80): Max retries exceeded with url: /archlinux/core/os/x86_64/core.db (Caused by NewConnectionError('<urllib3.connection.HTTPConnection object at 0x7fb447e4b200>: Failed to establish a new connection: [Errno -2] Name or service not known'))
ERROR:root:[ERROR] Attempt 3 failed to connect to https://mirror.reisenbauer.ee/archlinux/: HTTPSConnectionPool(host='mirror.reisenbauer.ee', port=443): Max retries exceeded with url: /archlinux/core/os/x86_64/core.db (Caused by NewConnectionError('<urllib3.connection.HTTPSConnection object at 0x7fb447e4a660>: Failed to establish a new connection: [Errno -2] Name or service not known'))
ERROR:root:[ERROR] Attempt 1 failed to connect to http://archlinux.mirror.ba/: 404 Client Error: Not Found for url: http://archlinux.mirror.ba/core/os/x86_64/core.db
ERROR:root:[ERROR] Attempt 2 failed to connect to http://archlinux.mirror.ba/: 404 Client Error: Not Found for url: http://archlinux.mirror.ba/core/os/x86_64/core.db
ERROR:root:[ERROR] Attempt 2 failed to connect to https://mirror.hostart.az/archlinux/: HTTPSConnectionPool(host='mirror.hostart.az', port=443): Max retries exceeded with url: /archlinux/core/os/x86_64/core.db (Caused by NewConnectionError('<urllib3.connection.HTTPSConnection object at 0x7fb447d50c80>: Failed to establish a new connection: [Errno 113] No route to host'))
ERROR:root:[ERROR] Attempt 2 failed to connect to http://mirror.hostart.az/archlinux/: HTTPConnectionPool(host='mirror.hostart.az', port=80): Max retries exceeded with url: /archlinux/core/os/x86_64/core.db (Caused by NewConnectionError('<urllib3.connection.HTTPConnection object at 0x7fb447d50860>: Failed to establish a new connection: [Errno 113] No route to host'))
ERROR:root:[ERROR] Attempt 3 failed to connect to http://archlinux.mirror.ba/: 404 Client Error: Not Found for url: http://archlinux.mirror.ba/core/os/x86_64/core.db
ERROR:root:[ERROR] Attempt 1 failed to connect to https://www.caco.ic.unicamp.br/archlinux/: HTTPSConnectionPool(host='www.caco.ic.unicamp.br', port=443): Max retries exceeded with url: /archlinux/core/os/x86_64/core.db (Caused by NewConnectionError('<urllib3.connection.HTTPSConnection object at 0x7fb447e4a3c0>: Failed to establish a new connection: [Errno -2] Name or service not known'))
ERROR:root:[ERROR] Attempt 1 failed to connect to http://www.caco.ic.unicamp.br/archlinux/: HTTPConnectionPool(host='www.caco.ic.unicamp.br', port=80): Max retries exceeded with url: /archlinux/core/os/x86_64/core.db (Caused by NewConnectionError('<urllib3.connection.HTTPConnection object at 0x7fb447e4be60>: Failed to establish a new connection: [Errno -2] Name or service not known'))
ERROR:root:[ERROR] Attempt 3 failed to connect to http://mirror.hostart.az/archlinux/: HTTPConnectionPool(host='mirror.hostart.az', port=80): Max retries exceeded with url: /archlinux/core/os/x86_64/core.db (Caused by NewConnectionError('<urllib3.connection.HTTPConnection object at 0x7fb447e8f080>: Failed to establish a new connection: [Errno 113] No route to host'))
ERROR:root:[ERROR] Attempt 3 failed to connect to https://mirror.hostart.az/archlinux/: HTTPSConnectionPool(host='mirror.hostart.az', port=443): Max retries exceeded with url: /archlinux/core/os/x86_64/core.db (Caused by NewConnectionError('<urllib3.connection.HTTPSConnection object at 0x7fb447e8d3a0>: Failed to establish a new connection: [Errno 113] No route to host'))
ERROR:root:[ERROR] Attempt 2 failed to connect to http://www.caco.ic.unicamp.br/archlinux/: HTTPConnectionPool(host='www.caco.ic.unicamp.br', port=80): Max retries exceeded with url: /archlinux/core/os/x86_64/core.db (Caused by NewConnectionError('<urllib3.connection.HTTPConnection object at 0x7fb447d27d40>: Failed to establish a new connection: [Errno -2] Name or service not known'))
ERROR:root:[ERROR] Attempt 2 failed to connect to https://www.caco.ic.unicamp.br/archlinux/: HTTPSConnectionPool(host='www.caco.ic.unicamp.br', port=443): Max retries exceeded with url: /archlinux/core/os/x86_64/core.db (Caused by NewConnectionError('<urllib3.connection.HTTPSConnection object at 0x7fb447d27560>: Failed to establish a new connection: [Errno -2] Name or service not known'))
ERROR:root:[ERROR] Attempt 3 failed to connect to http://www.caco.ic.unicamp.br/archlinux/: HTTPConnectionPool(host='www.caco.ic.unicamp.br', port=80): Max retries exceeded with url: /archlinux/core/os/x86_64/core.db (Caused by NewConnectionError('<urllib3.connection.HTTPConnection object at 0x7fb447e4a810>: Failed to establish a new connection: [Errno -2] Name or service not known'))
ERROR:root:[ERROR] Attempt 3 failed to connect to https://www.caco.ic.unicamp.br/archlinux/: HTTPSConnectionPool(host='www.caco.ic.unicamp.br', port=443): Max retries exceeded with url: /archlinux/core/os/x86_64/core.db (Caused by NewConnectionError('<urllib3.connection.HTTPSConnection object at 0x7fb447e4a750>: Failed to establish a new connection: [Errno -2] Name or service not known'))
ERROR:root:[ERROR] Attempt 1 failed to connect to http://mirror.cedille.club/archlinux/: HTTPConnectionPool(host='mirror.cedille.club', port=80): Max retries exceeded with url: /archlinux/core/os/x86_64/core.db (Caused by NewConnectionError('<urllib3.connection.HTTPConnection object at 0x7fb447e8fec0>: Failed to establish a new connection: [Errno 113] No route to host'))
ERROR:root:[ERROR] Attempt 1 failed to connect to https://mirror.darklinux.uk/archlinux/: HTTPSConnectionPool(host='mirror.darklinux.uk', port=443): Max retries exceeded with url: /archlinux/core/os/x86_64/core.db (Caused by ConnectTimeoutError(<urllib3.connection.HTTPSConnection object at 0x7fb447e8e210>, 'Connection to mirror.darklinux.uk timed out. (connect timeout=5)'))
ERROR:root:[ERROR] Attempt 1 failed to connect to http://archlinux.mirror.colo-serv.net/: HTTPConnectionPool(host='archlinux.mirror.colo-serv.net', port=80): Max retries exceeded with url: /core/os/x86_64/core.db (Caused by NewConnectionError('<urllib3.connection.HTTPConnection object at 0x7fb447e4b4d0>: Failed to establish a new connection: [Errno -2] Name or service not known'))
ERROR:root:[ERROR] Attempt 1 failed to connect to http://archlinux.pop-es.rnp.br/: HTTPConnectionPool(host='archlinux.pop-es.rnp.br', port=80): Max retries exceeded with url: /core/os/x86_64/core.db (Caused by NewConnectionError('<urllib3.connection.HTTPConnection object at 0x7fb447e4b0e0>: Failed to establish a new connection: [Errno 101] Network is unreachable'))
ERROR:root:[ERROR] Attempt 2 failed to connect to http://archlinux.mirror.colo-serv.net/: HTTPConnectionPool(host='archlinux.mirror.colo-serv.net', port=80): Max retries exceeded with url: /core/os/x86_64/core.db (Caused by NewConnectionError('<urllib3.connection.HTTPConnection object at 0x7fb447e4a7e0>: Failed to establish a new connection: [Errno -2] Name or service not known'))
ERROR:root:[ERROR] Attempt 3 failed to connect to http://archlinux.mirror.colo-serv.net/: HTTPConnectionPool(host='archlinux.mirror.colo-serv.net', port=80): Max retries exceeded with url: /core/os/x86_64/core.db (Caused by NewConnectionError('<urllib3.connection.HTTPConnection object at 0x7fb447e49ac0>: Failed to establish a new connection: [Errno -2] Name or service not known'))
ERROR:root:[ERROR] Attempt 2 failed to connect to http://mirror.cedille.club/archlinux/: HTTPConnectionPool(host='mirror.cedille.club', port=80): Max retries exceeded with url: /archlinux/core/os/x86_64/core.db (Caused by NewConnectionError('<urllib3.connection.HTTPConnection object at 0x7fb447d51160>: Failed to establish a new connection: [Errno 113] No route to host'))
ERROR:root:[ERROR] Attempt 2 failed to connect to https://mirror.darklinux.uk/archlinux/: HTTPSConnectionPool(host='mirror.darklinux.uk', port=443): Max retries exceeded with url: /archlinux/core/os/x86_64/core.db (Caused by ConnectTimeoutError(<urllib3.connection.HTTPSConnection object at 0x7fb447d50f20>, 'Connection to mirror.darklinux.uk timed out. (connect timeout=5)'))
ERROR:root:[ERROR] Attempt 1 failed to connect to http://elmirror.cl/archlinux/: 403 Client Error:  for url: http://elmirror.cl/archlinux/core/os/x86_64/core.db
ERROR:root:[ERROR] Attempt 2 failed to connect to http://archlinux.pop-es.rnp.br/: HTTPConnectionPool(host='archlinux.pop-es.rnp.br', port=80): Max retries exceeded with url: /core/os/x86_64/core.db (Caused by NewConnectionError('<urllib3.connection.HTTPConnection object at 0x7fb447d51a90>: Failed to establish a new connection: [Errno 101] Network is unreachable'))
ERROR:root:[ERROR] Attempt 1 failed to connect to https://elmirror.cl/archlinux/: ('Connection aborted.', ConnectionResetError(104, 'Connection reset by peer'))
ERROR:root:[ERROR] Attempt 3 failed to connect to http://mirror.cedille.club/archlinux/: HTTPConnectionPool(host='mirror.cedille.club', port=80): Max retries exceeded with url: /archlinux/core/os/x86_64/core.db (Caused by NewConnectionError('<urllib3.connection.HTTPConnection object at 0x7fb447d503e0>: Failed to establish a new connection: [Errno 113] No route to host'))
ERROR:root:[ERROR] Attempt 2 failed to connect to http://elmirror.cl/archlinux/: 403 Client Error:  for url: http://elmirror.cl/archlinux/core/os/x86_64/core.db
ERROR:root:[ERROR] Attempt 2 failed to connect to https://elmirror.cl/archlinux/: ('Connection aborted.', ConnectionResetError(104, 'Connection reset by peer'))
ERROR:root:[ERROR] Attempt 1 failed to connect to http://mirror.powerfly.ca/archlinux/: HTTPConnectionPool(host='mirror.powerfly.ca', port=80): Max retries exceeded with url: /archlinux/core/os/x86_64/core.db (Caused by NewConnectionError('<urllib3.connection.HTTPConnection object at 0x7fb447e8e300>: Failed to establish a new connection: [Errno 101] Network is unreachable'))
ERROR:root:[ERROR] Attempt 1 failed to connect to https://mirror.powerfly.ca/archlinux/: HTTPSConnectionPool(host='mirror.powerfly.ca', port=443): Max retries exceeded with url: /archlinux/core/os/x86_64/core.db (Caused by NewConnectionError('<urllib3.connection.HTTPSConnection object at 0x7fb447e8c200>: Failed to establish a new connection: [Errno 101] Network is unreachable'))
ERROR:root:[ERROR] Attempt 3 failed to connect to https://elmirror.cl/archlinux/: ('Connection aborted.', ConnectionResetError(104, 'Connection reset by peer'))
ERROR:root:[ERROR] Attempt 3 failed to connect to http://elmirror.cl/archlinux/: 403 Client Error:  for url: http://elmirror.cl/archlinux/core/os/x86_64/core.db
ERROR:root:[ERROR] Attempt 3 failed to connect to https://mirror.darklinux.uk/archlinux/: HTTPSConnectionPool(host='mirror.darklinux.uk', port=443): Max retries exceeded with url: /archlinux/core/os/x86_64/core.db (Caused by ConnectTimeoutError(<urllib3.connection.HTTPSConnection object at 0x7fb447d277a0>, 'Connection to mirror.darklinux.uk timed out. (connect timeout=5)'))
ERROR:root:[ERROR] Attempt 3 failed to connect to http://archlinux.pop-es.rnp.br/: HTTPConnectionPool(host='archlinux.pop-es.rnp.br', port=80): Max retries exceeded with url: /core/os/x86_64/core.db (Caused by NewConnectionError('<urllib3.connection.HTTPConnection object at 0x7fb447ea5580>: Failed to establish a new connection: [Errno 101] Network is unreachable'))
ERROR:root:[ERROR] Attempt 2 failed to connect to http://mirror.powerfly.ca/archlinux/: HTTPConnectionPool(host='mirror.powerfly.ca', port=80): Max retries exceeded with url: /archlinux/core/os/x86_64/core.db (Caused by NewConnectionError('<urllib3.connection.HTTPConnection object at 0x7fb447d52090>: Failed to establish a new connection: [Errno 101] Network is unreachable'))
ERROR:root:[ERROR] Attempt 2 failed to connect to https://mirror.powerfly.ca/archlinux/: HTTPSConnectionPool(host='mirror.powerfly.ca', port=443): Max retries exceeded with url: /archlinux/core/os/x86_64/core.db (Caused by NewConnectionError('<urllib3.connection.HTTPSConnection object at 0x7fb447d52330>: Failed to establish a new connection: [Errno 101] Network is unreachable'))
ERROR:root:[ERROR] Attempt 1 failed to connect to http://mirrors.hit.edu.cn/archlinux/: HTTPConnectionPool(host='mirrors.hit.edu.cn', port=80): Max retries exceeded with url: /archlinux/core/os/x86_64/core.db (Caused by NewConnectionError('<urllib3.connection.HTTPConnection object at 0x7fb447e8fb60>: Failed to establish a new connection: [Errno 101] Network is unreachable'))
ERROR:root:[ERROR] Attempt 1 failed to connect to https://mirrors.hit.edu.cn/archlinux/: HTTPSConnectionPool(host='mirrors.hit.edu.cn', port=443): Max retries exceeded with url: /archlinux/core/os/x86_64/core.db (Caused by NewConnectionError('<urllib3.connection.HTTPSConnection object at 0x7fb447e8d5e0>: Failed to establish a new connection: [Errno 101] Network is unreachable'))
ERROR:root:[ERROR] Attempt 3 failed to connect to https://mirror.powerfly.ca/archlinux/: HTTPSConnectionPool(host='mirror.powerfly.ca', port=443): Max retries exceeded with url: /archlinux/core/os/x86_64/core.db (Caused by NewConnectionError('<urllib3.connection.HTTPSConnection object at 0x7fb447d50860>: Failed to establish a new connection: [Errno 101] Network is unreachable'))
ERROR:root:[ERROR] Attempt 3 failed to connect to http://mirror.powerfly.ca/archlinux/: HTTPConnectionPool(host='mirror.powerfly.ca', port=80): Max retries exceeded with url: /archlinux/core/os/x86_64/core.db (Caused by NewConnectionError('<urllib3.connection.HTTPConnection object at 0x7fb447e4bb90>: Failed to establish a new connection: [Errno 101] Network is unreachable'))
ERROR:root:[ERROR] Attempt 1 failed to connect to https://mirrors.njupt.edu.cn/archlinux/: 403 Client Error: Forbidden for url: https://mirrors.njupt.edu.cn/archlinux/core/os/x86_64/core.db
ERROR:root:[ERROR] Attempt 2 failed to connect to https://mirrors.hit.edu.cn/archlinux/: HTTPSConnectionPool(host='mirrors.hit.edu.cn', port=443): Max retries exceeded with url: /archlinux/core/os/x86_64/core.db (Caused by NewConnectionError('<urllib3.connection.HTTPSConnection object at 0x7fb447d527b0>: Failed to establish a new connection: [Errno 101] Network is unreachable'))
ERROR:root:[ERROR] Attempt 2 failed to connect to http://mirrors.hit.edu.cn/archlinux/: HTTPConnectionPool(host='mirrors.hit.edu.cn', port=80): Max retries exceeded with url: /archlinux/core/os/x86_64/core.db (Caused by NewConnectionError('<urllib3.connection.HTTPConnection object at 0x7fb447d26960>: Failed to establish a new connection: [Errno 101] Network is unreachable'))
ERROR:root:[ERROR] Attempt 2 failed to connect to https://mirrors.njupt.edu.cn/archlinux/: 403 Client Error: Forbidden for url: https://mirrors.njupt.edu.cn/archlinux/core/os/x86_64/core.db
ERROR:root:[ERROR] Attempt 3 failed to connect to https://mirrors.njupt.edu.cn/archlinux/: 403 Client Error: Forbidden for url: https://mirrors.njupt.edu.cn/archlinux/core/os/x86_64/core.db
ERROR:root:[ERROR] Attempt 3 failed to connect to https://mirrors.hit.edu.cn/archlinux/: HTTPSConnectionPool(host='mirrors.hit.edu.cn', port=443): Max retries exceeded with url: /archlinux/core/os/x86_64/core.db (Caused by NewConnectionError('<urllib3.connection.HTTPSConnection object at 0x7fb447e8d9d0>: Failed to establish a new connection: [Errno 101] Network is unreachable'))
ERROR:root:[ERROR] Attempt 3 failed to connect to http://mirrors.hit.edu.cn/archlinux/: HTTPConnectionPool(host='mirrors.hit.edu.cn', port=80): Max retries exceeded with url: /archlinux/core/os/x86_64/core.db (Caused by NewConnectionError('<urllib3.connection.HTTPConnection object at 0x7fb447e8e210>: Failed to establish a new connection: [Errno 101] Network is unreachable'))
ERROR:root:[ERROR] Attempt 1 failed to connect to https://mirror.safe-con.dk/archlinux/: HTTPSConnectionPool(host='mirror.safe-con.dk', port=443): Max retries exceeded with url: /archlinux/core/os/x86_64/core.db (Caused by NewConnectionError('<urllib3.connection.HTTPSConnection object at 0x7fb44aa998e0>: Failed to establish a new connection: [Errno -2] Name or service not known'))
ERROR:root:[ERROR] Attempt 2 failed to connect to https://mirror.safe-con.dk/archlinux/: HTTPSConnectionPool(host='mirror.safe-con.dk', port=443): Max retries exceeded with url: /archlinux/core/os/x86_64/core.db (Caused by NewConnectionError('<urllib3.connection.HTTPSConnection object at 0x7fb44aa99700>: Failed to establish a new connection: [Errno -2] Name or service not known'))
ERROR:root:[ERROR] Attempt 1 failed to connect to https://arch.mcstrugs.org/: HTTPSConnectionPool(host='arch.mcstrugs.org', port=443): Max retries exceeded with url: /core/os/x86_64/core.db (Caused by NewConnectionError('<urllib3.connection.HTTPSConnection object at 0x7fb44a75dfa0>: Failed to establish a new connection: [Errno -2] Name or service not known'))
ERROR:root:[ERROR] Attempt 1 failed to connect to http://mirror.arctic.lol/ArchMirror/: HTTPConnectionPool(host='mirror.arctic.lol', port=80): Max retries exceeded with url: /ArchMirror/core/os/x86_64/core.db (Caused by NewConnectionError('<urllib3.connection.HTTPConnection object at 0x7fb447ebc770>: Failed to establish a new connection: [Errno -2] Name or service not known'))
ERROR:root:[ERROR] Attempt 1 failed to connect to https://mirror.arctic.lol/ArchMirror/: HTTPSConnectionPool(host='mirror.arctic.lol', port=443): Max retries exceeded with url: /ArchMirror/core/os/x86_64/core.db (Caused by NewConnectionError('<urllib3.connection.HTTPSConnection object at 0x7fb44aa2a4b0>: Failed to establish a new connection: [Errno -2] Name or service not known'))
ERROR:root:[ERROR] Attempt 1 failed to connect to https://mirrors.xjtu.edu.cn/archlinux/: HTTPSConnectionPool(host='mirrors.xjtu.edu.cn', port=443): Max retries exceeded with url: /archlinux/core/os/x86_64/core.db (Caused by NewConnectionError('<urllib3.connection.HTTPSConnection object at 0x7fb44aa2a090>: Failed to establish a new connection: [Errno 101] Network is unreachable'))
ERROR:root:[ERROR] Attempt 2 failed to connect to https://arch.mcstrugs.org/: HTTPSConnectionPool(host='arch.mcstrugs.org', port=443): Max retries exceeded with url: /core/os/x86_64/core.db (Caused by NewConnectionError('<urllib3.connection.HTTPSConnection object at 0x7fb447ea5be0>: Failed to establish a new connection: [Errno -2] Name or service not known'))
ERROR:root:[ERROR] Attempt 2 failed to connect to http://mirror.arctic.lol/ArchMirror/: HTTPConnectionPool(host='mirror.arctic.lol', port=80): Max retries exceeded with url: /ArchMirror/core/os/x86_64/core.db (Caused by NewConnectionError('<urllib3.connection.HTTPConnection object at 0x7fb44aa9aed0>: Failed to establish a new connection: [Errno -2] Name or service not known'))
ERROR:root:[ERROR] Attempt 2 failed to connect to https://mirror.arctic.lol/ArchMirror/: HTTPSConnectionPool(host='mirror.arctic.lol', port=443): Max retries exceeded with url: /ArchMirror/core/os/x86_64/core.db (Caused by NewConnectionError('<urllib3.connection.HTTPSConnection object at 0x7fb447ebf260>: Failed to establish a new connection: [Errno -2] Name or service not known'))
ERROR:root:[ERROR] Attempt 3 failed to connect to https://mirror.safe-con.dk/archlinux/: HTTPSConnectionPool(host='mirror.safe-con.dk', port=443): Max retries exceeded with url: /archlinux/core/os/x86_64/core.db (Caused by NewConnectionError('<urllib3.connection.HTTPSConnection object at 0x7fb447ebe390>: Failed to establish a new connection: [Errno -2] Name or service not known'))
ERROR:root:[ERROR] Attempt 3 failed to connect to https://arch.mcstrugs.org/: HTTPSConnectionPool(host='arch.mcstrugs.org', port=443): Max retries exceeded with url: /core/os/x86_64/core.db (Caused by NewConnectionError('<urllib3.connection.HTTPSConnection object at 0x7fb44aa9b320>: Failed to establish a new connection: [Errno -2] Name or service not known'))
ERROR:root:[ERROR] Attempt 3 failed to connect to http://mirror.arctic.lol/ArchMirror/: HTTPConnectionPool(host='mirror.arctic.lol', port=80): Max retries exceeded with url: /ArchMirror/core/os/x86_64/core.db (Caused by NewConnectionError('<urllib3.connection.HTTPConnection object at 0x7fb44aa99b20>: Failed to establish a new connection: [Errno -2] Name or service not known'))
ERROR:root:[ERROR] Attempt 1 failed to connect to http://archlinux.mirrors.benatherton.com/: HTTPConnectionPool(host='archlinux.mirrors.benatherton.com', port=80): Max retries exceeded with url: /core/os/x86_64/core.db (Caused by NewConnectionError('<urllib3.connection.HTTPConnection object at 0x7fb44aa9acc0>: Failed to establish a new connection: [Errno -5] No address associated with hostname'))
ERROR:root:[ERROR] Attempt 3 failed to connect to https://mirror.arctic.lol/ArchMirror/: HTTPSConnectionPool(host='mirror.arctic.lol', port=443): Max retries exceeded with url: /ArchMirror/core/os/x86_64/core.db (Caused by NewConnectionError('<urllib3.connection.HTTPSConnection object at 0x7fb447e8fad0>: Failed to establish a new connection: [Errno -2] Name or service not known'))
ERROR:root:[ERROR] Attempt 2 failed to connect to http://archlinux.mirrors.benatherton.com/: HTTPConnectionPool(host='archlinux.mirrors.benatherton.com', port=80): Max retries exceeded with url: /core/os/x86_64/core.db (Caused by NewConnectionError('<urllib3.connection.HTTPConnection object at 0x7fb447e8e0f0>: Failed to establish a new connection: [Errno -5] No address associated with hostname'))
